Workbook

Sheet 사전 서비스별 예측 비용
A1: AWS 실질 리소스 기준 서비스별 월 예상 비용
A2: 추후 사용할 스펙 AWS 공식 Price List/요금 페이지. 월 744시간/서울리전 기준
A4: 월 예상 비용 총합 (USD) | B4: =G29 -> 773.0435 | D4: 월 비용 산정 서비스 | E4: =COUNTA(B7:B28) -> 22 | G4: 추가 실측 기반 서비스 | H4: 2
A6: 카테고리 | B6: 서비스 | C6: 실제 구성·스펙 | D6: 리소스 수 | E6: AWS 적용 단가 | F6: 월 사용 기준 | G6: 월 예상 비용 (USD) | H6: 산정 범위/제외 항목 | I6: AWS 공식 출처
A7: 컴퓨팅 | B7: EC2 | C7: m7g.xlarge ×2 (mp-eks-node), t4g.xlarge ×1 (mp-ci-server), t3.medium ×1 (mp-dashboard), t3.micro ×1 (stopped) | D7: 5 | E7: m7g.xlarge $0.2006/h; t4g.xlarge $0.1664/h; t3.medium $0.0520/h | F7: running 4대 × 744시간; stopped 1대 컴퓨팅 비용 0 | G7: =IF(COUNTIFS('aws 전체 실질적 리소스 사용'!$B$2:$B$165,B7,'aws 전체 실질적 리소스 사용'!$I$2:$I$165,"<>")=0,"미산정",SUMIF('aws 전체 실질적 리소스 사용'!$B$2:$B$165,B7,'aws 전체 실질적 리소스 사용'!$I$2:$I$165)) -> 460.9824 | H7: 온디맨드 Linux/UNIX 기준; CPU Credit 추가 사용료 가능 | I7: https://aws.amazon.com/ec2/pricing/on-demand/
A8: 스토리지 | B8: EBS | C8: gp3 22개 · 총 530 GiB · 각 볼륨 기본 IOPS 3,000 | D8: 22 | E8: gp3 $0.08/GB-month (기본 3,000 IOPS 포함) | F8: 총 530 GiB provisioned | G8: =IF(COUNTIFS('aws 전체 실질적 리소스 사용'!$B$2:$B$165,B8,'aws 전체 실질적 리소스 사용'!$I$2:$I$165,"<>")=0,"미산정",SUMIF('aws 전체 실질적 리소스 사용'!$B$2:$B$165,B8,'aws 전체 실질적 리소스 사용'!$I$2:$I$165)) -> 42.4 | H8: 기본 3,000 IOPS 범위; 추가 IOPS/throughput 없음으로 계산 | I8: https://aws.amazon.com/ebs/pricing/
A9: 네트워크 | B9: Public IPv4 | C9: Elastic IP 4개 · 모두 associated | D9: 4 | E9: $0.005/IP-hour | F9: 4개 × 744시간 | G9: =IF(COUNTIFS('aws 전체 실질적 리소스 사용'!$B$2:$B$165,B9,'aws 전체 실질적 리소스 사용'!$I$2:$I$165,"<>")=0,"미산정",SUMIF('aws 전체 실질적 리소스 사용'!$B$2:$B$165,B9,'aws 전체 실질적 리소스 사용'!$I$2:$I$165)) -> 14.88 | I9: https://aws.amazon.com/vpc/pricing/
A10: 네트워크 | B10: NAT Gateway | C10: NAT Gateway 1개 · mp-nat · ap-northeast-2 | D10: 1 | E10: $0.059/GW-hour + $0.059/GB 처리 | F10: 744시간 + 6일 데이터 처리비 실측을 31일 환산 | G10: =0.059*744+0.362642/6*31 -> 45.76965 | H10: NAT 데이터 처리비 포함 · 08-10~08-15 실측 사용량 기준 월 환산 | I10: https://aws.amazon.com/vpc/pricing/
A11: 네트워크 | B11: Application Load Balancer | C11: 인터넷 공개형 ALB 1개 · mp-alb-public | D11: 1 | E11: $0.0225/ALB-hour + $0.008/LCU-hour | F11: 744시간 + 6일 LCU 실측을 31일 환산 | G11: =0.0225*744+0.000242/6*31 -> 16.74125 | H11: LCU 비용 포함 · 08-10~08-15 실측 사용량 기준 월 환산 | I11: https://aws.amazon.com/elasticloadbalancing/pricing/
A12: 데이터 | B12: ElastiCache | C12: Valkey · cache.t4g.micro ×2 | D12: 2 | E12: $0.0192/node-hour | F12: 2노드 × 744시간 | G12: =IF(COUNTIFS('aws 전체 실질적 리소스 사용'!$B$2:$B$165,B12,'aws 전체 실질적 리소스 사용'!$I$2:$I$165,"<>")=0,"미산정",SUMIF('aws 전체 실질적 리소스 사용'!$B$2:$B$165,B12,'aws 전체 실질적 리소스 사용'!$I$2:$I$165)) -> 28.5696 | H12: 노드 시간 비용 기준 | I12: https://aws.amazon.com/elasticache/pricing/
A13: 네트워크 | B13: VPC Endpoint | C13: Gateway(S3) ×2 + Interface(STS/SQS/Secrets Manager) ×3 · Interface는 각 2 AZ | D13: 5 | E13: Gateway $0; Interface $0.013/AZ-hour + 데이터 처리량 별도 | F13: Interface 3개 × 2 AZ × 744시간; Gateway 2개 $0 | G13: =3*2*744*0.013 -> 58.032 | H13: Interface Endpoint 시간비 포함 · 데이터 처리비는 수집 파일에 별도 금액 없음 | I13: https://aws.amazon.com/privatelink/pricing/
A14: 컨테이너 | B14: EKS Control Plane | C14: EKS 클러스터 1개 · mp-eks · 표준 지원 | D14: 1 | E14: $0.10/cluster-hour (표준 지원) | F14: 1클러스터 × 744시간 | G14: =IF(COUNTIFS('aws 전체 실질적 리소스 사용'!$B$2:$B$165,B14,'aws 전체 실질적 리소스 사용'!$I$2:$I$165,"<>")=0,"미산정",SUMIF('aws 전체 실질적 리소스 사용'!$B$2:$B$165,B14,'aws 전체 실질적 리소스 사용'!$I$2:$I$165)) -> 74.4 | I14: https://aws.amazon.com/eks/pricing/
A15: 보안 | B15: Secrets Manager | C15: Secret 11개 | D15: 11 | E15: $0.40/secret-month + API 호출 별도 | F15: 11개 × 1개월 | G15: =IF(COUNTIFS('aws 전체 실질적 리소스 사용'!$B$2:$B$165,B15,'aws 전체 실질적 리소스 사용'!$I$2:$I$165,"<>")=0,"미산정",SUMIF('aws 전체 실질적 리소스 사용'!$B$2:$B$165,B15,'aws 전체 실질적 리소스 사용'!$I$2:$I$165)) -> 4.4 | H15: API 호출 비용 제외 | I15: https://aws.amazon.com/secrets-manager/pricing/
A16: 네트워크 | B16: Route 53 | C16: Public Hosted Zone 1개 · newdrops.cloud · records 4 | D16: 1 | E16: $0.50/hosted-zone-month + DNS query 별도 | F16: Hosted Zone 1개 × 1개월 | G16: =IF(COUNTIFS('aws 전체 실질적 리소스 사용'!$B$2:$B$165,B16,'aws 전체 실질적 리소스 사용'!$I$2:$I$165,"<>")=0,"미산정",SUMIF('aws 전체 실질적 리소스 사용'!$B$2:$B$165,B16,'aws 전체 실질적 리소스 사용'!$I$2:$I$165)) -> 0.5 | H16: DNS query 비용 제외 | I16: https://aws.amazon.com/route53/pricing/
A17: 네트워크 | B17: VPC | C17: VPC 4개 (ap-northeast-2 3개, us-east-1 1개) | D17: 4 | E17: 리소스 자체 고정 사용료 $0 | F17: 4개 리소스 | G17: =IF(COUNTIFS('aws 전체 실질적 리소스 사용'!$B$2:$B$165,B17,'aws 전체 실질적 리소스 사용'!$I$2:$I$165,"<>")=0,"미산정",SUMIF('aws 전체 실질적 리소스 사용'!$B$2:$B$165,B17,'aws 전체 실질적 리소스 사용'!$I$2:$I$165)) -> 0 | H17: 해당 리소스 자체 고정 사용료 기준 $0 | I17: https://aws.amazon.com/vpc/pricing/
A18: 네트워크 | B18: Subnet | C18: Subnet 17개 | D18: 17 | E18: 리소스 자체 고정 사용료 $0 | F18: 17개 리소스 | G18: =IF(COUNTIFS('aws 전체 실질적 리소스 사용'!$B$2:$B$165,B18,'aws 전체 실질적 리소스 사용'!$I$2:$I$165,"<>")=0,"미산정",SUMIF('aws 전체 실질적 리소스 사용'!$B$2:$B$165,B18,'aws 전체 실질적 리소스 사용'!$I$2:$I$165)) -> 0 | H18: 해당 리소스 자체 고정 사용료 기준 $0 | I18: https://aws.amazon.com/vpc/pricing/
A19: 네트워크 | B19: Internet Gateway | C19: Internet Gateway 4개 | D19: 4 | E19: 리소스 자체 고정 사용료 $0 | F19: 4개 리소스 | G19: =IF(COUNTIFS('aws 전체 실질적 리소스 사용'!$B$2:$B$165,B19,'aws 전체 실질적 리소스 사용'!$I$2:$I$165,"<>")=0,"미산정",SUMIF('aws 전체 실질적 리소스 사용'!$B$2:$B$165,B19,'aws 전체 실질적 리소스 사용'!$I$2:$I$165)) -> 0 | H19: 해당 리소스 자체 고정 사용료 기준 $0 | I19: https://aws.amazon.com/vpc/pricing/
A20: 네트워크 | B20: Route Table | C20: Route Table 8개 | D20: 8 | E20: 리소스 자체 고정 사용료 $0 | F20: 8개 리소스 | G20: =IF(COUNTIFS('aws 전체 실질적 리소스 사용'!$B$2:$B$165,B20,'aws 전체 실질적 리소스 사용'!$I$2:$I$165,"<>")=0,"미산정",SUMIF('aws 전체 실질적 리소스 사용'!$B$2:$B$165,B20,'aws 전체 실질적 리소스 사용'!$I$2:$I$165)) -> 0 | H20: 해당 리소스 자체 고정 사용료 기준 $0 | I20: https://aws.amazon.com/vpc/pricing/
A21: 네트워크 | B21: Security Group | C21: Security Group 13개 | D21: 13 | E21: 리소스 자체 고정 사용료 $0 | F21: 13개 리소스 | G21: =IF(COUNTIFS('aws 전체 실질적 리소스 사용'!$B$2:$B$165,B21,'aws 전체 실질적 리소스 사용'!$I$2:$I$165,"<>")=0,"미산정",SUMIF('aws 전체 실질적 리소스 사용'!$B$2:$B$165,B21,'aws 전체 실질적 리소스 사용'!$I$2:$I$165)) -> 0 | H21: 해당 리소스 자체 고정 사용료 기준 $0 | I21: https://aws.amazon.com/vpc/pricing/
A22: 네트워크 | B22: Network ACL | C22: Network ACL 4개 | D22: 4 | E22: 리소스 자체 고정 사용료 $0 | F22: 4개 리소스 | G22: =IF(COUNTIFS('aws 전체 실질적 리소스 사용'!$B$2:$B$165,B22,'aws 전체 실질적 리소스 사용'!$I$2:$I$165,"<>")=0,"미산정",SUMIF('aws 전체 실질적 리소스 사용'!$B$2:$B$165,B22,'aws 전체 실질적 리소스 사용'!$I$2:$I$165)) -> 0 | H22: 해당 리소스 자체 고정 사용료 기준 $0 | I22: https://aws.amazon.com/vpc/pricing/
A23: 컨테이너 | B23: ECR | C23: ECR Repository 18개 · 리포지토리당 이미지 1 GB 저장 가정 | D23: 18 | E23: $0.10/GB-month | F23: 18개 × 1 GB = 18 GB 저장 | G23: =18*1*0.1 -> 1.8 | H23: 동일 리전 이미지 Pull 전송료 $0 가정 · 실제 이미지 저장량에 따라 변동 | I23: https://aws.amazon.com/ecr/pricing/
A24: 서버리스 | B24: Lambda | C24: Lambda Function 11개 · 함수당 월 100,000회 · 512 MB · 평균 200 ms 실행 가정 | D24: 11 | E24: $0.20/100만 요청 + $0.0000166667/GB-second | F24: 총 110만 호출 · 110,000 GB-second | G24: =(1100000/1000000*0.2)+(1100000*0.2*0.5*0.0000166667) -> 2.053337 | H24: 무료 티어 미적용한 보수적 계산 · 실제 호출 수/메모리/실행시간에 따라 변동 | I24: https://aws.amazon.com/lambda/pricing/
A25: 메시징 | B25: SQS | C25: Queue 11개 · 큐당 월 100,000 요청 가정 | D25: 11 | E25: $0.40/100만 Standard 요청 가정 | F25: 총 110만 요청 | G25: =(1100000/1000000)*0.4 -> 0.44 | H25: 무료 티어 미적용 · Standard Queue 기준 · payload 64 KB 이하 가정 | I25: https://aws.amazon.com/sqs/pricing/
A26: 스토리지 | B26: S3 | C26: Bucket 17개 · 버킷당 평균 1 GB S3 Standard 저장 가정 | D26: 17 | E26: $0.025/GB-month (서울 S3 Standard 가정) | F26: 17개 × 1 GB = 17 GB 저장 | G26: =17*1*0.025 -> 0.425 | H26: 저장 비용만 산정 · PUT/GET·인터넷 전송량은 사용량 미수집으로 제외 | I26: https://aws.amazon.com/s3/pricing/
A27: 모니터링 | B27: CloudWatch Logs | C27: EKS control-plane / Glue 로그 수집 | D27: 1 | E27: $0.76/GB 수집 기준(수집 파일 스펙) | F27: 08-10~08-15 실측비 $4.173597 → 31일 환산 | G27: =4.173597/6*31 -> 21.563585 | H27: 평균 사용량과 비교 | I27: aws_cost_daily_summary_plain.xlsx
A28: AI | B28: Amazon Bedrock | C28: Nova Micro + Titan V2 · 6일 총 85회 호출 | D28: 1 | E28: 입·출력 토큰 사용량 기반 | F28: 08-10~08-15 실측비 $0.016776 → 31일 환산 | G28: =0.016776/6*31 -> 0.086676 | H28: 실측 6일 비용을 31일로 환산한 월 예상치 | I28: aws_cost_daily_summary_plain.xlsx
F29: 월 예상 비용 합계 (기존 리소스 + CloudWatch/Bedrock + 실측 변동비 반영) | G29: =SUM(G7:G28) -> 773.0435

Sheet aws 전체 실질적 리소스 사용
A1: 카테고리 | B1: 서비스 | C1: 리전 | D1: 리소스 ID | E1: 이름 | F1: 유형 | G1: 상태 | H1: 사양/범위 | I1: 월 예상 (USD) | J1: 단가 | K1: 계산 근거 | L1: 출처
A2: 컴퓨팅 | B2: EC2 | C2: ap-northeast-2 | D2: i-0f4ebb39e84735bb2 | E2: mp-eks-node | F2: EC2 m7g.xlarge | G2: running | H2: Linux/UNIX | I2: 149.2464 | J2: 0.2006 | K2: 실행 744시간 × AWS Price List 온디맨드 단가 | L2: AWS 서비스 API 직접 조회
A3: 컴퓨팅 | B3: EC2 | C3: ap-northeast-2 | D3: i-081c03fd82281e841 | E3: mp-ci-server | F3: EC2 t4g.xlarge | G3: running | H3: Linux/UNIX | I3: 123.8016 | J3: 0.1664 | K3: 실행 744시간 × AWS Price List 온디맨드 단가 | L3: AWS 서비스 API 직접 조회
A4: 컴퓨팅 | B4: EC2 | C4: ap-northeast-2 | D4: i-0b28079e87febf176 | E4: mp-dashboard | F4: EC2 t3.medium | G4: running | H4: Linux/UNIX | I4: 38.688 | J4: 0.052 | K4: 실행 744시간 × AWS Price List 온디맨드 단가 | L4: AWS 서비스 API 직접 조회
A5: 컴퓨팅 | B5: EC2 | C5: ap-northeast-2 | D5: i-0c840eb9011d3f29b | E5: mp-eks-node | F5: EC2 m7g.xlarge | G5: running | H5: Linux/UNIX | I5: 149.2464 | J5: 0.2006 | K5: 실행 744시간 × AWS Price List 온디맨드 단가 | L5: AWS 서비스 API 직접 조회
A6: 스토리지 | B6: EBS | C6: ap-northeast-2 | D6: vol-05fe7e8e1e3abbaf1 | E6: mp-ebs-ci-docker | F6: gp3 | G6: in-use | H6: 60 GiB · IOPS 3000 | I6: 4.8 | J6: 0.08 | K6: GB-month × AWS Price List gp3 단가 | L6: AWS 서비스 API 직접 조회
A7: 스토리지 | B7: EBS | C7: ap-northeast-2 | D7: vol-0e274819289db6807 | E7: mp-eks-dynamic-pvc-8da72e60-c4b6-420c-bed2-a61091e0950c | F7: gp3 | G7: in-use | H7: 32 GiB · IOPS 3000 | I7: 2.56 | J7: 0.08 | K7: GB-month × AWS Price List gp3 단가 | L7: AWS 서비스 API 직접 조회
A8: 스토리지 | B8: EBS | C8: ap-northeast-2 | D8: vol-0f13422adfd78f1da | E8: mp-eks-dynamic-pvc-222105c1-e91e-485c-805b-e3a9d5dbd615 | F8: gp3 | G8: in-use | H8: 20 GiB · IOPS 3000 | I8: 1.6 | J8: 0.08 | K8: GB-month × AWS Price List gp3 단가 | L8: AWS 서비스 API 직접 조회
A9: 스토리지 | B9: EBS | C9: ap-northeast-2 | D9: vol-03ea1ffa7007ca669 | E9: mp-eks-dynamic-pvc-7b8de393-4de0-4d37-933f-5319e7a1ddaa | F9: gp3 | G9: in-use | H9: 64 GiB · IOPS 3000 | I9: 5.12 | J9: 0.08 | K9: GB-month × AWS Price List gp3 단가 | L9: AWS 서비스 API 직접 조회
A10: 스토리지 | B10: EBS | C10: ap-northeast-2 | D10: vol-09385421128c9abed | E10: mp-eks-dynamic-pvc-6bc00f34-599e-4750-8f64-ee584a7fe7c6 | F10: gp3 | G10: in-use | H10: 1 GiB · IOPS 3000 | I10: 0.08 | J10: 0.08 | K10: GB-month × AWS Price List gp3 단가 | L10: AWS 서비스 API 직접 조회
A11: 스토리지 | B11: EBS | C11: ap-northeast-2 | D11: vol-0f8f42200eb748458 | E11: mp-eks-dynamic-pvc-194fe2b5-6892-4f36-8f35-e8c69c1c383c | F11: gp3 | G11: in-use | H11: 10 GiB · IOPS 3000 | I11: 0.8 | J11: 0.08 | K11: GB-month × AWS Price List gp3 단가 | L11: AWS 서비스 API 직접 조회
A12: 스토리지 | B12: EBS | C12: ap-northeast-2 | D12: vol-053bb1edb01923a0d | E12: mp-ebs-ci-root | F12: gp3 | G12: in-use | H12: 30 GiB · IOPS 3000 | I12: 2.4 | J12: 0.08 | K12: GB-month × AWS Price List gp3 단가 | L12: AWS 서비스 API 직접 조회
A13: 스토리지 | B13: EBS | C13: ap-northeast-2 | D13: vol-04c65b842a240f882 | E13: mp-eks-dynamic-pvc-50af5270-8aca-49a9-9c96-d059ce16ee04 | F13: gp3 | G13: available | H13: 1 GiB · IOPS 3000 | I13: 0.08 | J13: 0.08 | K13: GB-month × AWS Price List gp3 단가 | L13: AWS 서비스 API 직접 조회
... A30: 네트워크 | B30: Public IPv4 | C30: ap-northeast-2 | D30: eipalloc-09625065746b8164f | E30: <EIP> | F30: Elastic IP | G30: associated | H30: eni-03c985bced24a7b0c | I30: 3.72 | J30: 0.005 | K30: 공인 IPv4 744시간 × $0.005 | L30: AWS 서비스 API 직접 조회
A31: 네트워크 | B31: NAT Gateway | C31: ap-northeast-2 | D31: nat-0dcdcec898e31a423 | E31: mp-nat | F31: NAT Gateway | G31: available | H31: subnet-051694c5fe4d0e1b6 | I31: =0.059*744+0.362642/6*31 -> 45.76965 | J31: $0.059/GW-hour + $0.059/GB 처리 | K31: 시간비 $0.059 × 744시간 + 08-10~08-15 NAT 데이터 처리 실측비 $0.362642 ÷ 6일 × 31일 | L31: aws_cost_daily_summary_plain.xlsx 상세 내역 + 기존 AWS 단가표
A32: 네트워크 | B32: Application Load Balancer | C32: ap-northeast-2 | D32: arn:aws:elasticloadbalancing:ap-northeast-2:<ACCOUNT_ID>:loadbalancer/app/mp-alb-public/764f4168e39fe43d | E32: mp-alb-public | F32: ALB | G32: active | H32: internet-facing | I32: =0.0225*744+0.000242/6*31 -> 16.74125 | J32: $0.0225/ALB-hour + $0.008/LCU-hour | K32: ALB 시간비 $0.0225 × 744시간 + 08-10~08-15 LCU 실측비 $0.000242 ÷ 6일 × 31일 | L32: aws_cost_daily_summary_plain.xlsx 상세 내역 + 기존 AWS 단가표
A33: 데이터 | B33: ElastiCache | C33: ap-northeast-2 | D33: mp-cache-001 | E33: mp-cache-001 | F33: cache.t4g.micro | G33: available | H33: valkey | I33: 14.2848 | J33: 0.0192 | K33: 노드 1개 × 744시간 × 노드 시간 단가 | L33: AWS 서비스 API 직접 조회
A34: 데이터 | B34: ElastiCache | C34: ap-northeast-2 | D34: mp-cache-002 | E34: mp-cache-002 | F34: cache.t4g.micro | G34: available | H34: valkey | I34: 14.2848 | J34: 0.0192 | K34: 노드 1개 × 744시간 × 노드 시간 단가 | L34: AWS 서비스 API 직접 조회
A35: 네트워크 | B35: VPC Endpoint | C35: ap-northeast-2 | D35: vpce-090a918b3a59d6ab8 | E35: mp-vpce-ci-s3 | F35: Gateway | G35: available | H35: com.amazonaws.ap-northeast-2.s3 · 0 AZ | I35: 0 | J35: 0 | K35: Gateway Endpoint 자체 사용료 $0 | L35: AWS 서비스 API 직접 조회
A36: 네트워크 | B36: VPC Endpoint | C36: ap-northeast-2 | D36: vpce-0ec59f760c2bd1282 | E36: mp-vpce-s3 | F36: Gateway | G36: available | H36: com.amazonaws.ap-northeast-2.s3 · 0 AZ | I36: 0 | J36: 0 | K36: Gateway Endpoint 자체 사용료 $0 | L36: AWS 서비스 API 직접 조회
A37: 네트워크 | B37: VPC Endpoint | C37: ap-northeast-2 | D37: vpce-0abf45fa959ca25c0 | E37: mp-vpce-sts | F37: Interface | G37: available | H37: com.amazonaws.ap-northeast-2.sts · 2 AZ | I37: =2*744*0.013 -> 19.344 | J37: 0.013 | K37: Interface Endpoint 2 AZ × 744시간 × $0.013/AZ-hour = $19.344/월; 데이터 처리비 제외 | L37: aws_cost_daily_summary_plain.xlsx 상세 내역 + 기존 AWS 단가표
A38: 네트워크 | B38: VPC Endpoint | C38: ap-northeast-2 | D38: vpce-0372bec184461994f | E38: mp-vpce-sqs | F38: Interface | G38: available | H38: com.amazonaws.ap-northeast-2.sqs · 2 AZ | I38: =2*744*0.013 -> 19.344 | J38: 0.013 | K38: Interface Endpoint 2 AZ × 744시간 × $0.013/AZ-hour = $19.344/월; 데이터 처리비 제외 | L38: aws_cost_daily_summary_plain.xlsx 상세 내역 + 기존 AWS 단가표
A39: 네트워크 | B39: VPC Endpoint | C39: ap-northeast-2 | D39: vpce-0252a21d62a579289 | E39: mp-vpce-secretsmanager | F39: Interface | G39: available | H39: com.amazonaws.ap-northeast-2.secretsmanager · 2 AZ | I39: =2*744*0.013 -> 19.344 | J39: 0.013 | K39: Interface Endpoint 2 AZ × 744시간 × $0.013/AZ-hour = $19.344/월; 데이터 처리비 제외 | L39: aws_cost_daily_summary_plain.xlsx 상세 내역 + 기존 AWS 단가표
A40: 네트워크 | B40: VPC | C40: ap-northeast-2 | D40: vpc-0cbc077b708599115 | E40: mp-vpc-service | F40: VPC | G40: available | H40: 10.10.0.0/16 | I40: 0 | J40: 0 | K40: VPC 자체 사용료 $0 | L40: AWS 서비스 API 직접 조회
A41: 네트워크 | B41: VPC | C41: ap-northeast-2 | D41: vpc-0c2c65e7dc87b7e67 | E41: vpc-0c2c65e7dc87b7e67 | F41: VPC | G41: available | H41: 172.31.0.0/16 | I41: 0 | J41: 0 | K41: VPC 자체 사용료 $0 | L41: AWS 서비스 API 직접 조회
A42: 네트워크 | B42: VPC | C42: ap-northeast-2 | D42: vpc-0956da9710438ef92 | E42: mp-vpc-ci | F42: VPC | G42: available | H42: 10.11.0.0/16 | I42: 0 | J42: 0 | K42: VPC 자체 사용료 $0 | L42: AWS 서비스 API 직접 조회
A43: 네트워크 | B43: Subnet | C43: ap-northeast-2 | D43: subnet-0aa43f0d46c8eb5c8 | E43: mp-subnet-data-ap-northeast-2b | F43: Subnet | G43: available | H43: 10.10.33.0/24 | I43: 0 | J43: 0 | K43: Subnet 자체 사용료 $0 | L43: AWS 서비스 API 직접 조회
A44: 네트워크 | B44: Subnet | C44: ap-northeast-2 | D44: subnet-084afc3164acd0e1c | E44: mp-subnet-ci-public | F44: Subnet | G44: available | H44: 10.11.0.0/24 | I44: 0 | J44: 0 | K44: Subnet 자체 사용료 $0 | L44: AWS 서비스 API 직접 조회
A45: 네트워크 | B45: Subnet | C45: ap-northeast-2 | D45: subnet-051694c5fe4d0e1b6 | E45: mp-subnet-public-ap-northeast-2a | F45: Subnet | G45: available | H45: 10.10.0.0/24 | I45: 0 | J45: 0 | K45: Subnet 자체 사용료 $0 | L45: AWS 서비스 API 직접 조회
A46: 네트워크 | B46: Subnet | C46: ap-northeast-2 | D46: subnet-05dd3778a7f5c0e57 | E46: mp-subnet-data-ap-northeast-2a | F46: Subnet | G46: available | H46: 10.10.32.0/24 | I46: 0 | J46: 0 | K46: Subnet 자체 사용료 $0 | L46: AWS 서비스 API 직접 조회
A47: 네트워크 | B47: Subnet | C47: ap-northeast-2 | D47: subnet-0d07175d6ee640010 | E47: mp-subnet-node-ap-northeast-2b | F47: Subnet | G47: available | H47: 10.10.80.0/20 | I47: 0 | J47: 0 | K47: Subnet 자체 사용료 $0 | L47: AWS 서비스 API 직접 조회
A48: 네트워크 | B48: Subnet | C48: ap-northeast-2 | D48: subnet-0ff0f1728991239bf | E48: subnet-0ff0f1728991239bf | F48: Subnet | G48: available | H48: 172.31.32.0/20 | I48: 0 | J48: 0 | K48: Subnet 자체 사용료 $0 | L48: AWS 서비스 API 직접 조회
A49: 네트워크 | B49: Subnet | C49: ap-northeast-2 | D49: subnet-084a72faf36293e15 | E49: mp-subnet-node-ap-northeast-2a | F49: Subnet | G49: available | H49: 10.10.64.0/20 | I49: 0 | J49: 0 | K49: Subnet 자체 사용료 $0 | L49: AWS 서비스 API 직접 조회
A50: 네트워크 | B50: Subnet | C50: ap-northeast-2 | D50: subnet-018f515c2299bb994 | E50: subnet-018f515c2299bb994 | F50: Subnet | G50: available | H50: 172.31.16.0/20 | I50: 0 | J50: 0 | K50: Subnet 자체 사용료 $0 | L50: AWS 서비스 API 직접 조회
A51: 네트워크 | B51: Subnet | C51: ap-northeast-2 | D51: subnet-067b4c416bb97806f | E51: subnet-067b4c416bb97806f | F51: Subnet | G51: available | H51: 172.31.0.0/20 | I51: 0 | J51: 0 | K51: Subnet 자체 사용료 $0 | L51: AWS 서비스 API 직접 조회
... A77: 네트워크 | B77: Network ACL | C77: ap-northeast-2 | D77: acl-0ee904fd36f031494 | E77: acl-0ee904fd36f031494 | F77: Network ACL | G77: active | H77: vpc-0c2c65e7dc87b7e67 | I77: 0 | J77: 0 | K77: Network ACL 자체 사용료 $0 | L77: AWS 서비스 API 직접 조회
A78: 컨테이너 | B78: ECR | C78: ap-northeast-2 | D78: arn:aws:ecr:ap-northeast-2:<ACCOUNT_ID>:repository/mealplanning/mp-notify-service | E78: mealplanning/mp-notify-service | F78: Repository | G78: active | H78: 1 GB 이미지 저장 가정 | I78: =J78*1 -> 0.1 | J78: 0.1 | K78: Repository당 1 GB × $0.10/GB-month = $0.10/월 (추정) | L78: https://aws.amazon.com/ecr/pricing/
A79: 컨테이너 | B79: ECR | C79: ap-northeast-2 | D79: arn:aws:ecr:ap-northeast-2:<ACCOUNT_ID>:repository/mealplanning/mp-pgsync | E79: mealplanning/mp-pgsync | F79: Repository | G79: active | H79: 1 GB 이미지 저장 가정 | I79: =J79*1 -> 0.1 | J79: 0.1 | K79: Repository당 1 GB × $0.10/GB-month = $0.10/월 (추정) | L79: https://aws.amazon.com/ecr/pricing/
A80: 컨테이너 | B80: ECR | C80: ap-northeast-2 | D80: arn:aws:ecr:ap-northeast-2:<ACCOUNT_ID>:repository/mealplanning/mp-video-service | E80: mealplanning/mp-video-service | F80: Repository | G80: active | H80: 1 GB 이미지 저장 가정 | I80: =J80*1 -> 0.1 | J80: 0.1 | K80: Repository당 1 GB × $0.10/GB-month = $0.10/월 (추정) | L80: https://aws.amazon.com/ecr/pricing/
A81: 컨테이너 | B81: ECR | C81: ap-northeast-2 | D81: arn:aws:ecr:ap-northeast-2:<ACCOUNT_ID>:repository/mealplanning/mp-price-service | E81: mealplanning/mp-price-service | F81: Repository | G81: active | H81: 1 GB 이미지 저장 가정 | I81: =J81*1 -> 0.1 | J81: 0.1 | K81: Repository당 1 GB × $0.10/GB-month = $0.10/월 (추정) | L81: https://aws.amazon.com/ecr/pricing/
...

Sheet 절감안
A1: AWS 월 비용 절감 시나리오 비교
A2: PPT에 표시된 5개 개선 항목을 동일 기준으로 정리 · 각 항목은 독립 시나리오이므로 절감액 단순 합산 금지
A4: No. | B4: 개선 항목 | C4: 기존 방식 | D4: 개선 방식 | E4: 기존 월비용 | F4: 개선 월비용 | G4: 월 절감액 | H4: 절감률 | I4: 비고
A5: 1 | B5: 컴퓨팅 아키텍처 | C5: Intel/AMD x86 m7i.xlarge×2 + t3.xlarge×1 | D5: Graviton m7g.xlarge×2 + t4g.xlarge×1 | E5: 527.87 | F5: 422.29 | G5: =E5-F5 -> 105.58 | H5: =IF(E5=0,0,G5/E5) -> 0.20001137 | I5: 동급 사양 비교
A6: 2 | B6: 비동기 처리 | C6: Kafka + Graviton + gp3 100GiB | D6: EventBridge + SQS | E6: 45.6 | F6: 9.04 | G6: =E6-F6 -> 36.56 | H6: =IF(E6=0,0,G6/E6) -> 0.80175439 | I6: 요청량이 크지 않은 비동기 처리 기준
A7: 3 | B7: EBS 볼륨 | C7: gp2 350GiB | D7: gp3 350GiB | E7: 53 | F7: 42.2 | G7: =E7-F7 -> 10.8 | H7: =IF(E7=0,0,G7/E7) -> 0.20377358 | I7: PPT 기준 동일 용량 비교
A8: 4 | B8: 운영 방식 | C8: ElastiCache + 완전관리형 DB/검색 계열 | D8: ElastiCache 유지 + Graviton 기반 직접 운영 | E8: 330 | F8: 137.19 | G8: =E8-F8 -> 192.81 | H8: =IF(E8=0,0,G8/E8) -> 0.58427273 | I8: 관리형 사용 범위를 줄인 시나리오
A9: 5 | B9: 모니터링 | C9: AWS 관리형 중심 모니터링 | D9: CloudWatch 제한 사용 + Prometheus/Grafana/Kubecost 직접 운영 | E9: 106.31 | F9: 61.06 | G9: =E9-F9 -> 45.25 | H9: =IF(E9=0,0,G9/E9) -> 0.42564199 | I9: 내부 모니터링 스택 활용
A11: 비용 합계 | D11: 개선 비용 합계
A13: =SUM(E5:E9) -> 1062.78 | D13: =SUM(F5:F9) -> 671.78
K15: \
